Workbook

Sheet Summary
A1: VIP scores and p-values by contrast — summary
A2: Untargeted LC-MS, 301 confidently annotated (L1/L2) metabolites. One sheet per contrast; every sheet holds all 301 metabolites sorted by VIP descending.
A4: Contrast | B4: Tissue | C4: Comparison | D4: n control | E4: n treated | F4: Metabolites | G4: p < 0.05 | H4: FDR < 0.05 | I4: VIP > 1 | J4: VIP > 1 AND p < 0.05
A5: scW control vs CSDS | B5: scW | C5: control vs CSDS | D5: 6 | E5: 6 | F5: =COUNT('scW control vs CSDS'!$N$7:$N$307) -> 301 | G5: =COUNTIF('scW control vs CSDS'!$O$7:$O$307,"<0.05") -> 91 | H5: =COUNTIF('scW control vs CSDS'!$P$7:$P$307,"<0.05") -> 0 | I5: =COUNTIF('scW control vs CSDS'!$N$7:$N$307,">1") -> 45 | J5: =COUNTIFS('scW control vs CSDS'!$N$7:$N$307,">1",'scW control vs CSDS'!$O$7:$O$307,"<0.05") -> 25
A6: BAT control vs CMVS | B6: BAT | C6: control vs CMVS | D6: 6 | E6: 5 | F6: =COUNT('BAT control vs CMVS'!$N$7:$N$307) -> 301 | G6: =COUNTIF('BAT control vs CMVS'!$O$7:$O$307,"<0.05") -> 32 | H6: =COUNTIF('BAT control vs CMVS'!$P$7:$P$307,"<0.05") -> 0 | I6: =COUNTIF('BAT control vs CMVS'!$N$7:$N$307,">1") -> 36 | J6: =COUNTIFS('BAT control vs CMVS'!$N$7:$N$307,">1",'BAT control vs CMVS'!$O$7:$O$307,"<0.05") -> 12
A7: BAT control vs CSDS | B7: BAT | C7: control vs CSDS | D7: 6 | E7: 6 | F7: =COUNT('BAT control vs CSDS'!$N$7:$N$307) -> 301 | G7: =COUNTIF('BAT control vs CSDS'!$O$7:$O$307,"<0.05") -> 31 | H7: =COUNTIF('BAT control vs CSDS'!$P$7:$P$307,"<0.05") -> 0 | I7: =COUNTIF('BAT control vs CSDS'!$N$7:$N$307,">1") -> 35 | J7: =COUNTIFS('BAT control vs CSDS'!$N$7:$N$307,">1",'BAT control vs CSDS'!$O$7:$O$307,"<0.05") -> 6
A8: scW control vs CMVS | B8: scW | C8: control vs CMVS | D8: 6 | E8: 6 | F8: =COUNT('scW control vs CMVS'!$N$7:$N$307) -> 301 | G8: =COUNTIF('scW control vs CMVS'!$O$7:$O$307,"<0.05") -> 118 | H8: =COUNTIF('scW control vs CMVS'!$P$7:$P$307,"<0.05") -> 49 | I8: =COUNTIF('scW control vs CMVS'!$N$7:$N$307,">1") -> 41 | J8: =COUNTIFS('scW control vs CMVS'!$N$7:$N$307,">1",'scW control vs CMVS'!$O$7:$O$307,"<0.05") -> 26
A11: Method notes
A12: VIP: PLS-DA, 2 components, Pareto scaling, no log transform (the preprocessing that reproduces the reference SIMCA model).
A13: p-value: Welch two-sample t-test on raw peak areas (does not assume equal variances).
A14: FDR: Benjamini-Hochberg, computed within each contrast across all 301 metabolites.
A15: |r| with group: point-biserial correlation between peak area and group membership.
A16: Sample BAT_Aq_CMVS6 is excluded from both BAT contrasts as a multivariate outlier.
A18: How to read VIP against the p-value
A19: VIP is proportional to sqrt(SD) x |r| — it rewards BOTH how large a metabolite's peak is and how consistent the group difference is.
A20: The t-statistic behind the p-value divides the size out, so it responds to consistency alone.
A21: A metabolite can therefore have a high VIP and a poor p-value simply because its peak is large.
A22: Check the 'Peak area rank' column before interpreting any high VIP with a non-significant p-value.
A24: Caution
... A26: The BAT control vs CSDS model fails permutation validation (p = 0.098), so its VIP ranking should not be used to nominate biomarkers.

Sheet scW control vs CSDS
A1: scW: control vs CSDS — VIP scores and p-values
A2: All 301 confidently annotated (L1/L2) metabolites, sorted by VIP descending. n = 6 control vs 6 CSDS.
A3: VIP from PLS-DA, 2 components, Pareto scaling, no log transform. p-value = Welch t-test (unequal variances). FDR = Benjamini-Hochberg across all 301 metabolites.
A4: VIP > 1 means an above-average contribution to the model; it is NOT a significance test and carries no error control.
A6: Metabolite | B6: KEGG ID | C6: Annotation confidence | D6: m/z | E6: RT (min) | F6: Mean peak area (control) | G6: SD (control) | H6: Mean peak area (CSDS) | I6: SD (CSDS) | J6: Mean peak area (all) | K6: Fold change | L6: log2 fold change | M6: |r| with group | N6: VIP score | O6: p-value (Welch) | P6: FDR q-value (BH) | Q6: VIP rank | R6: p-value rank | S6: Peak area rank | T6: Significant (p<0.05) | U6: Passes FDR<0.05 | V6: VIP > 1
A7: Creatine | B7: C00300 | C7: High | D7: 132.07663 | E7: 11.358 | F7: 1.2824011e+09 | G7: 8.2581931e+08 | H7: 1.3503935e+09 | I7: 1.7754567e+08 | J7: 1.3163973e+09 | K7: 1.0530196 | L7: 0.074532254 | M7: 0.062229485 | N7: 7.2861852 | O7: 0.85082601 | P7: 0.90175574 | Q7: =RANK(N7,$N$7:$N$307,0) -> 1 | R7: =RANK(O7,$O$7:$O$307,1) -> 284 | S7: =RANK(J7,$J$7:$J$307,0) -> 1 | T7: =IF(O7<0.05,"YES","no") -> no | U7: =IF(P7<0.05,"YES","no") -> no | V7: =IF(N7>1,"YES","no") -> YES
A8: L-Carnitine | B8: C00318 | C8: High | D8: 162.11233 | E8: 11.266 | F8: 1.0404348e+09 | G8: 3.8512585e+08 | H8: 1.579049e+09 | I8: 4.1531854e+08 | J8: 1.3097419e+09 | K8: 1.5176818 | L8: 0.60186937 | M8: 0.59306987 | N8: 6.0995966 | O8: 0.042236206 | P8: 0.15286924 | Q8: =RANK(N8,$N$7:$N$307,0) -> 2 | R8: =RANK(O8,$O$7:$O$307,1) -> 83 | S8: =RANK(J8,$J$7:$J$307,0) -> 2 | T8: =IF(O8<0.05,"YES","no") -> YES | U8: =IF(P8<0.05,"YES","no") -> no | V8: =IF(N8>1,"YES","no") -> YES
A9: O-Acetyl-L-carnitine | C9: High | D9: 204.12298 | E9: 10.121 | F9: 4.4674362e+08 | G9: 2.5248505e+08 | H9: 4.431879e+08 | I9: 1.1848228e+08 | J9: 4.4496576e+08 | K9: 0.9920408 | L9: -0.011528645 | M9: 0.0098748303 | N9: 4.7219901 | O9: 0.97594706 | P9: 0.98773343 | Q9: =RANK(N9,$N$7:$N$307,0) -> 3 | R9: =RANK(O9,$O$7:$O$307,1) -> 297 | S9: =RANK(J9,$J$7:$J$307,0) -> 4 | T9: =IF(O9<0.05,"YES","no") -> no | U9: =IF(P9<0.05,"YES","no") -> no | V9: =IF(N9>1,"YES","no") -> YES
A10: Betaine | C10: High | D10: 118.08616 | E10: 10.135 | F10: 5.1986313e+08 | G10: 1.8674074e+08 | H10: 7.7309701e+08 | I10: 1.5590403e+08 | J10: 6.4648007e+08 | K10: 1.4871164 | L10: 0.57251762 | M10: 0.62769846 | N10: 4.2593615 | O10: 0.029534489 | P10: 0.11740817 | Q10: =RANK(N10,$N$7:$N$307,0) -> 4 | R10: =RANK(O10,$O$7:$O$307,1) -> 75 | S10: =RANK(J10,$J$7:$J$307,0) -> 3 | T10: =IF(O10<0.05,"YES","no") -> YES | U10: =IF(P10<0.05,"YES","no") -> no | V10: =IF(N10>1,"YES","no") -> YES
A11: Glutamine | C11: High | D11: 147.07637 | E11: 11.11 | F11: 1.9557461e+08 | G11: 67193449 | H11: 3.2520134e+08 | I11: 50444058 | J11: 2.6038797e+08 | K11: 1.6627994 | L11: 0.73361413 | M11: 0.76691431 | N11: 3.431913 | O11: 0.0041240248 | P11: 0.080425433 | Q11: =RANK(N11,$N$7:$N$307,0) -> 5 | R11: =RANK(O11,$O$7:$O$307,1) -> 14 | S11: =RANK(J11,$J$7:$J$307,0) -> 8 | T11: =IF(O11<0.05,"YES","no") -> YES | U11: =IF(P11<0.05,"YES","no") -> no | V11: =IF(N11>1,"YES","no") -> YES
A12: Taurine | B12: D00047 | C12: High | D12: 126.0218 | E12: 10.855 | F12: 3.0995749e+08 | G12: 1.0747099e+08 | H12: 4.4043485e+08 | I12: 65994926 | J12: 3.7519617e+08 | K12: 1.4209524 | L12: 0.50685824 | M12: 0.62535209 | N12: 3.0406753 | O12: 0.0340345 | P12: 0.12967575 | Q12: =RANK(N12,$N$7:$N$307,0) -> 6 | R12: =RANK(O12,$O$7:$O$307,1) -> 79 | S12: =RANK(J12,$J$7:$J$307,0) -> 5 | T12: =IF(O12<0.05,"YES","no") -> YES | U12: =IF(P12<0.05,"YES","no") -> no | V12: =IF(N12>1,"YES","no") -> YES
A13: Niacinamide | C13: High | D13: 123.05518 | E13: 6.893 | F13: 1.6886508e+08 | G13: 42910269 | H13: 2.7001906e+08 | I13: 54910642 | J13: 2.1944207e+08 | K13: 1.5990225 | L13: 0.67719024 | M13: 0.74721614 | N13: 3.0204891 | O13: 0.0057061123 | P13: 0.080769209 | Q13: =RANK(N13,$N$7:$N$307,0) -> 7 | R13: =RANK(O13,$O$7:$O$307,1) -> 18 | S13: =RANK(J13,$J$7:$J$307,0) -> 9 | T13: =IF(O13<0.05,"YES","no") -> YES | U13: =IF(P13<0.05,"YES","no") -> no | V13: =IF(N13>1,"YES","no") -> YES
A14: Lactic Acid | B14: D02111 | C14: Medium | D14: 89.02433 | E14: 7.221 | F14: 2.6361209e+08 | G14: 2.3743605e+08 | H14: 3.5165817e+08 | I14: 1.1059324e+08 | J14: 3.0763513e+08 | K14: 1.3339986 | L14: 0.41575721 | M14: 0.25197538 | N14: 2.9264233 | O14: 0.43717162 | P14: 0.57462296 | Q14: =RANK(N14,$N$7:$N$307,0) -> 8 | R14: =RANK(O14,$O$7:$O$307,1) -> 229 | S14: =RANK(J14,$J$7:$J$307,0) -> 7 | T14: =IF(O14<0.05,"YES","no") -> no | U14: =IF(P14<0.05,"YES","no") -> no | V14: =IF(N14>1,"YES","no") -> YES
A15: L-Proline | C15: High | D15: 116.07051 | E15: 10.722 | F15: 1.631018e+08 | G15: 91496712 | H15: 2.6626456e+08 | I15: 45270066 | J15: 2.1468318e+08 | K15: 1.6325054 | L15: 0.70708776 | M15: 0.6163951 | N15: 2.7063172 | O15: 0.041093627 | P15: 0.15084368 | Q15: =RANK(N15,$N$7:$N$307,0) -> 9 | R15: =RANK(O15,$O$7:$O$307,1) -> 82 | S15: =RANK(J15,$J$7:$J$307,0) -> 10 | T15: =IF(O15<0.05,"YES","no") -> YES | U15: =IF(P15<0.05,"YES","no") -> no | V15: =IF(N15>1,"YES","no") -> YES
A16: Glutamate | C16: High | D16: 148.06035 | E16: 9.8 | F16: 1.4105361e+08 | G16: 44267005 | H16: 2.0792754e+08 | I16: 22216327 | J16: 1.7449057e+08 | K16: 1.474103 | L16: 0.55983729 | M16: 0.72277444 | N16: 2.3993749 | O16: 0.012068495 | P16: 0.080769209 | Q16: =RANK(N16,$N$7:$N$307,0) -> 10 | R16: =RANK(O16,$O$7:$O$307,1) -> 43 | S16: =RANK(J16,$J$7:$J$307,0) -> 12 | T16: =IF(O16<0.05,"YES","no") -> YES | U16: =IF(P16<0.05,"YES","no") -> no | V16: =IF(N16>1,"YES","no") -> YES
A17: AMP | C17: High | D17: 348.07036 | E17: 9.071 | F17: 1.0860347e+08 | G17: 41235866 | H17: 1.7573888e+08 | I17: 34497529 | J17: 1.4217117e+08 | K17: 1.61817 | L17: 0.6943632 | M17: 0.69524198 | N17: 2.3167952 | O17: 0.012491723 | P17: 0.080769209 | Q17: =RANK(N17,$N$7:$N$307,0) -> 11 | R17: =RANK(O17,$O$7:$O$307,1) -> 46 | S17: =RANK(J17,$J$7:$J$307,0) -> 14 | T17: =IF(O17<0.05,"YES","no") -> YES | U17: =IF(P17<0.05,"YES","no") -> no | V17: =IF(N17>1,"YES","no") -> YES
A18: DELTA-VALEROBETAINE | C18: Medium | D18: 160.13315 | E18: 12.211 | F18: 52606281 | G18: 16530598 | H18: 99230047 | I18: 22862417 | J18: 75918164 | K18: 1.8862776 | L18: 0.91554198 | M18: 0.78804494 | N18: 2.2105074 | O18: 0.0028247159 | P18: 0.077294499 | Q18: =RANK(N18,$N$7:$N$307,0) -> 12 | R18: =RANK(O18,$O$7:$O$307,1) -> 11 | S18: =RANK(J18,$J$7:$J$307,0) -> 25 | T18: =IF(O18<0.05,"YES","no") -> YES | U18: =IF(P18<0.05,"YES","no") -> no | V18: =IF(N18>1,"YES","no") -> YES
A19: Phosphoric acid | C19: Medium | D19: 96.96949 | E19: 10.445 | F19: 1.3852018e+08 | G19: 67269447 | H19: 2.0610002e+08 | I19: 33383156 | J19: 1.723101e+08 | K19: 1.48787 | L19: 0.57324846 | M19: 0.57184069 | N19: 2.1836297 | O19: 0.061661299 | P19: 0.17286825 | Q19: =RANK(N19,$N$7:$N$307,0) -> 13 | R19: =RANK(O19,$O$7:$O$307,1) -> 105 | S19: =RANK(J19,$J$7:$J$307,0) -> 13 | T19: =IF(O19<0.05,"YES","no") -> no | U19: =IF(P19<0.05,"YES","no") -> no | V19: =IF(N19>1,"YES","no") -> YES
A20: L-Histidine | C20: High | D20: 156.0766 | E20: 13.639 | F20: 78099745 | G20: 39852249 | H20: 1.3559064e+08 | I20: 23308909 | J20: 1.0684519e+08 | K20: 1.7361214 | L20: 0.79586787 | M20: 0.69423958 | N20: 2.1360453 | O20: 0.015670737 | P20: 0.09070946 | Q20: =RANK(N20,$N$7:$N$307,0) -> 14 | R20: =RANK(O20,$O$7:$O$307,1) -> 52 | S20: =RANK(J20,$J$7:$J$307,0) -> 17 | T20: =IF(O20<0.05,"YES","no") -> YES | U20: =IF(P20<0.05,"YES","no") -> no | V20: =IF(N20>1,"YES","no") -> YES
A21: Adenosine | C21: High | D21: 268.104 | E21: 8.014 | F21: 1.5018848e+08 | G21: 43538726 | H21: 2.1461859e+08 | I21: 56093350 | J21: 1.8240353e+08 | K21: 1.428995 | L21: 0.51500085 | M21: 0.57502331 | N21: 2.0492153 | O21: 0.052056776 | P21: 0.16669244 | Q21: =RANK(N21,$N$7:$N$307,0) -> 15 | R21: =RANK(O21,$O$7:$O$307,1) -> 94 | S21: =RANK(J21,$J$7:$J$307,0) -> 11 | T21: =IF(O21<0.05,"YES","no") -> no | U21: =IF(P21<0.05,"YES","no") -> no | V21: =IF(N21>1,"YES","no") -> YES
A22: Urocanate | C22: High | D22: 139.05016 | E22: 8.782 | F22: 88609977 | G22: 50115635 | H22: 74377174 | I22: 14913124 | J22: 81493575 | K22: 0.83937697 | L22: -0.25260922 | M22: 0.20631145 | N22: 2.0140382 | O22: 0.53020956 | P22: 0.67055916 | Q22: =RANK(N22,$N$7:$N$307,0) -> 16 | R22: =RANK(O22,$O$7:$O$307,1) -> 238 | S22: =RANK(J22,$J$7:$J$307,0) -> 23 | T22: =IF(O22<0.05,"YES","no") -> no | U22: =IF(P22<0.05,"YES","no") -> no | V22: =IF(N22>1,"YES","no") -> YES
A23: Phosphorylcholine | C23: High | D23: 184.07327 | E23: 11.86 | F23: 48471179 | G23: 41271154 | H23: 1.0411296e+08 | I23: 42733611 | J23: 76292070 | K23: 2.1479354 | L23: 1.1029506 | M23: 0.58721909 | N23: 1.9482106 | O23: 0.044726849 | P23: 0.15488998 | Q23: =RANK(N23,$N$7:$N$307,0) -> 17 | R23: =RANK(O23,$O$7:$O$307,1) -> 86 | S23: =RANK(J23,$J$7:$J$307,0) -> 24 | T23: =IF(O23<0.05,"YES","no") -> YES | U23: =IF(P23<0.05,"YES","no") -> no | V23: =IF(N23>1,"YES","no") -> YES
A24: Phenylalanine | C24: High | D24: 166.08629 | E24: 8.757 | F24: 33378282 | G24: 13592983 | H24: 67706988 | I24: 13011525 | J24: 50542635 | K24: 2.0284743 | L24: 1.0203951 | M24: 0.81629229 | N24: 1.8346305 | O24: 0.0012053514 | P24: 0.063570933 | Q24: =RANK(N24,$N$7:$N$307,0) -> 18 | R24: =RANK(O24,$O$7:$O$307,1) -> 5 | S24: =RANK(J24,$J$7:$J$307,0) -> 31 | T24: =IF(O24<0.05,"YES","no") -> YES | U24: =IF(P24<0.05,"YES","no") -> no | V24: =IF(N24>1,"YES","no") -> YES
A25: L-Arginine | B25: C02385 | C25: High | D25: 175.11886 | E25: 18.84 | F25: 43043162 | G25: 28798034 | H25: 82926199 | I25: 19826977 | J25: 62984680 | K25: 1.9265824 | L25: 0.94604392 | M25: 0.66214274 | N25: 1.7293375 | O25: 0.021198088 | P25: 0.09969726 | Q25: =RANK(N25,$N$7:$N$307,0) -> 19 | R25: =RANK(O25,$O$7:$O$307,1) -> 64 | S25: =RANK(J25,$J$7:$J$307,0) -> 28 | T25: =IF(O25<0.05,"YES","no") -> YES | U25: =IF(P25<0.05,"YES","no") -> no | V25: =IF(N25>1,"YES","no") -> YES
A26: Sarcosine | C26: High | D26: 90.05487 | E26: 11.327 | F26: 72135994 | G26: 41774655 | H26: 72674987 | I26: 19194799 | J26: 72405490 | K26: 1.0074719 | L26: 0.010739593 | M26: 0.0090809858 | N26: 1.661842 | O26: 0.97788891 | P26: 0.98773343 | Q26: =RANK(N26,$N$7:$N$307,0) -> 20 | R26: =RANK(O26,$O$7:$O$307,1) -> 298 | S26: =RANK(J26,$J$7:$J$307,0) -> 27 | T26: =IF(O26<0.05,"YES","no") -> no | U26: =IF(P26<0.05,"YES","no") -> no | V26: =IF(N26>1,"YES","no") -> YES
A27: Glycerophosphocholine | C27: Medium | D27: 258.11003 | E27: 11.271 | F27: 94270142 | G27: 44420088 | H27: 1.3497819e+08 | I27: 26962783 | J27: 1.1462417e+08 | K27: 1.4318234 | L27: 0.51785352 | M27: 0.51877927 | N27: 1.6282339 | O27: 0.090181976 | P27: 0.21806569 | Q27: =RANK(N27,$N$7:$N$307,0) -> 21 | R27: =RANK(O27,$O$7:$O$307,1) -> 123 | S27: =RANK(J27,$J$7:$J$307,0) -> 16 | T27: =IF(O27<0.05,"YES","no") -> no | U27: =IF(P27<0.05,"YES","no") -> no | V27: =IF(N27>1,"YES","no") -> YES
A28: Methionine | B28: D00019 | C28: High | D28: 150.05829 | E28: 9.553 | F28: 42117273 | G28: 27398158 | H28: 77976460 | I28: 19363355 | J28: 60046866 | K28: 1.8514128 | L28: 0.88862664 | M28: 0.63771675 | N28: 1.6090825 | O28: 0.027904476 | P28: 0.11740817 | Q28: =RANK(N28,$N$7:$N$307,0) -> 22 | R28: =RANK(O28,$O$7:$O$307,1) -> 71 | S28: =RANK(J28,$J$7:$J$307,0) -> 29 | T28: =IF(O28<0.05,"YES","no") -> YES | U28: =IF(P28<0.05,"YES","no") -> no | V28: =IF(N28>1,"YES","no") -> YES
A29: Pantothenate | C29: High | D29: 220.11801 | E29: 6.937 | F29: 66071055 | G29: 16105017 | H29: 1.0671319e+08 | I29: 45082312 | J29: 86392124 | K29: 1.6151278 | L29: 0.69164829 | M29: 0.54944754 | N29: 1.607552 | O29: 0.080883698 | P29: 0.20458818 | Q29: =RANK(N29,$N$7:$N$307,0) -> 23 | R29: =RANK(O29,$O$7:$O$307,1) -> 119 | S29: =RANK(J29,$J$7:$J$307,0) -> 22 | T29: =IF(O29<0.05,"YES","no") -> no | U29: =IF(P29<0.05,"YES","no") -> no | V29: =IF(N29>1,"YES","no") -> YES
A30: Anserine | C30: High | D30: 241.12961 | E30: 11.667 | F30: 9969130.1 | G30: 21933574 | H30: 1327576.7 | I30: 1377034 | J30: 5648353.4 | K30: 0.13316876 | L30: -2.9086724 | M30: 0.29136637 | N30: 1.582129 | O30: 0.37936998 | P30: 0.536105 | Q30: =RANK(N30,$N$7:$N$307,0) -> 24 | R30: =RANK(O30,$O$7:$O$307,1) -> 213 | S30: =RANK(J30,$J$7:$J$307,0) -> 96 | T30: =IF(O30<0.05,"YES","no") -> no | U30: =IF(P30<0.05,"YES","no") -> no | V30: =IF(N30>1,"YES","no") -> YES
A31: Glutathione Reduced | B31: C02471 | C31: High | D31: 308.09115 | E31: 9.381 | F31: 73540694 | G31: 27932941 | H31: 1.0843343e+08 | I31: 35709784 | J31: 90987060 | K31: 1.4744684 | L31: 0.56019486 | M31: 0.51206461 | N31: 1.529785 | O31: 0.090471158 | P31: 0.21806569 | Q31: =RANK(N31,$N$7:$N$307,0) -> 25 | R31: =RANK(O31,$O$7:$O$307,1) -> 124 | S31: =RANK(J31,$J$7:$J$307,0) -> 19 | T31: =IF(O31<0.05,"YES","no") -> no | U31: =IF(P31<0.05,"YES","no") -> no | V31: =IF(N31>1,"YES","no") -> YES
A32: Histamine | C32: Medium | D32: 112.08688 | E32: 11.095 | F32: 1.6597984e+08 | G32: 86253112 | H32: 1.1494643e+08 | I32: 55245649 | J32: 1.4046313e+08 | K32: 0.69253249 | L32: -0.53004633 | M32: 0.3600466 | N32: 1.4863141 | O32: 0.25503871 | P32: 0.4196804 | Q32: =RANK(N32,$N$7:$N$307,0) -> 26 | R32: =RANK(O32,$O$7:$O$307,1) -> 182 | S32: =RANK(J32,$J$7:$J$307,0) -> 15 | T32: =IF(O32<0.05,"YES","no") -> no | U32: =IF(P32<0.05,"YES","no") -> no | V32: =IF(N32>1,"YES","no") -> YES
A33: Stachydrine | C33: High | D33: 144.10188 | E33: 10.062 | F33: 78536226 | G33: 30798804 | H33: 1.0980655e+08 | I33: 15647724 | J33: 94171389 | K33: 1.3981644 | L33: 0.48353396 | M33: 0.57409489 | N33: 1.4775995 | O33: 0.059995897 | P33: 0.17286825 | Q33: =RANK(N33,$N$7:$N$307,0) -> 27 | R33: =RANK(O33,$O$7:$O$307,1) -> 104 | S33: =RANK(J33,$J$7:$J$307,0) -> 18 | T33: =IF(O33<0.05,"YES","no") -> no | U33: =IF(P33<0.05,"YES","no") -> no | V33: =IF(N33>1,"YES","no") -> YES
A34: Deoxycarnitine | C34: High | D34: 146.11753 | E34: 11.962 | F34: 28471696 | G34: 6904145.6 | H34: 51464129 | I34: 13853863 | J34: 39967913 | K34: 1.807554 | L34: 0.85403878 | M34: 0.75477178 | N34: 1.4559629 | O34: 0.0076530831 | P34: 0.080769209 | Q34: =RANK(N34,$N$7:$N$307,0) -> 28 | R34: =RANK(O34,$O$7:$O$307,1) -> 24 | S34: =RANK(J34,$J$7:$J$307,0) -> 39 | T34: =IF(O34<0.05,"YES","no") -> YES | U34: =IF(P34<0.05,"YES","no") -> no | V34: =IF(N34>1,"YES","no") -> YES
A35: Hypoxanthine | C35: High | D35: 175.00169 | E35: 8.607 | F35: 14646463 | G35: 4677960 | H35: 34011463 | I35: 15636884 | J35: 24328963 | K35: 2.3221621 | L35: 1.2154687 | M35: 0.67666965 | N35: 1.4335251 | O35: 0.027708393 | P35: 0.11740817 | Q35: =RANK(N35,$N$7:$N$307,0) -> 29 | R35: =RANK(O35,$O$7:$O$307,1) -> 70 | S35: =RANK(J35,$J$7:$J$307,0) -> 49 | T35: =IF(O35<0.05,"YES","no") -> YES | U35: =IF(P35<0.05,"YES","no") -> no | V35: =IF(N35>1,"YES","no") -> YES
A36: Propionylcarnitine | B36: C03017 | C36: Medium | D36: 218.13866 | E36: 9.458 | F36: 34639711 | G36: 12028070 | H36: 26974645 | I36: 9850367.5 | J36: 30807178 | K36: 0.77872026 | L36: -0.36082294 | M36: 0.35676812 | N36: 1.3356073 | O36: 0.25600773 | P36: 0.4196804 | Q36: =RANK(N36,$N$7:$N$307,0) -> 30 | R36: =RANK(O36,$O$7:$O$307,1) -> 183 | S36: =RANK(J36,$J$7:$J$307,0) -> 42 | T36: =IF(O36<0.05,"YES","no") -> no | U36: =IF(P36<0.05,"YES","no") -> no | V36: =IF(N36>1,"YES","no") -> YES
A37: Inosine | C37: High | D37: 269.08805 | E37: 8.957 | F37: 8178938.8 | G37: 4682154.3 | H37: 24455760 | I37: 11702228 | J37: 16317350 | K37: 2.9900897 | L37: 1.5801887 | M37: 0.70721383 | N37: 1.2765699 | O37: 0.017279729 | P37: 0.09631849 | Q37: =RANK(N37,$N$7:$N$307,0) -> 31 | R37: =RANK(O37,$O$7:$O$307,1) -> 54 | S37: =RANK(J37,$J$7:$J$307,0) -> 60 | T37: =IF(O37<0.05,"YES","no") -> YES | U37: =IF(P37<0.05,"YES","no") -> no | V37: =IF(N37>1,"YES","no") -> YES
A38: Tyrosine | B38: D00022 | C38: High | D38: 182.08114 | E38: 10.237 | F38: 17944354 | G38: 11895499 | H38: 35868353 | I38: 6126717.4 | J38: 26906354 | K38: 1.9988656 | L38: 0.9991815 | M38: 0.72003735 | N38: 1.2530577 | O38: 0.012266264 | P38: 0.080769209 | Q38: =RANK(N38,$N$7:$N$307,0) -> 32 | R38: =RANK(O38,$O$7:$O$307,1) -> 44 | S38: =RANK(J38,$J$7:$J$307,0) -> 47 | T38: =IF(O38<0.05,"YES","no") -> YES | U38: =IF(P38<0.05,"YES","no") -> no | V38: =IF(N38>1,"YES","no") -> YES
A39: Creatinine | C39: High | D39: 114.06614 | E39: 8.762 | F39: 40889713 | G39: 32096943 | H39: 51268663 | I39: 12056704 | J39: 46079188 | K39: 1.2538279 | L39: 0.32633932 | M39: 0.22828698 | N39: 1.2250382 | O39: 0.48477524 | P39: 0.62625471 | Q39: =RANK(N39,$N$7:$N$307,0) -> 33 | R39: =RANK(O39,$O$7:$O$307,1) -> 233 | S39: =RANK(J39,$J$7:$J$307,0) -> 35 | T39: =IF(O39<0.05,"YES","no") -> no | U39: =IF(P39<0.05,"YES","no") -> no | V39: =IF(N39>1,"YES","no") -> YES
A40: L-Lysine | C40: High | D40: 147.11272 | E40: 18.232 | F40: 32765810 | G40: 26559509 | H40: 51014631 | I40: 29850409 | J40: 41890220 | K40: 1.5569471 | L40: 0.63871988 | M40: 0.33352248 | N40: 1.1836283 | O40: 0.28974479 | P40: 0.45188177 | Q40: =RANK(N40,$N$7:$N$307,0) -> 34 | R40: =RANK(O40,$O$7:$O$307,1) -> 193 | S40: =RANK(J40,$J$7:$J$307,0) -> 37 | T40: =IF(O40<0.05,"YES","no") -> no | U40: =IF(P40<0.05,"YES","no") -> no | V40: =IF(N40>1,"YES","no") -> YES
A41: 4-Aminobenzoic acid | B41: D02907 | C41: Medium | D41: 138.0549 | E41: 10.341 | F41: 36465558 | G41: 14446596 | H41: 55724389 | I41: 11623109 | J41: 46094974 | K41: 1.5281376 | L41: 0.61177442 | M41: 0.62685348 | N41: 1.1784014 | O41: 0.030111822 | P41: 0.11740817 | Q41: =RANK(N41,$N$7:$N$307,0) -> 35 | R41: =RANK(O41,$O$7:$O$307,1) -> 77 | S41: =RANK(J41,$J$7:$J$307,0) -> 34 | T41: =IF(O41<0.05,"YES","no") -> YES | U41: =IF(P41<0.05,"YES","no") -> no | V41: =IF(N41>1,"YES","no") -> YES
...

Sheet BAT control vs CMVS
A1: BAT: control vs CMVS — VIP scores and p-values
A2: All 301 confidently annotated (L1/L2) metabolites, sorted by VIP descending. n = 6 control vs 5 CMVS.
A3: VIP from PLS-DA, 2 components, Pareto scaling, no log transform. p-value = Welch t-test (unequal variances). FDR = Benjamini-Hochberg across all 301 metabolites. Sample BAT_Aq_CMVS6 excluded as a multivariate outlier.
A4: VIP > 1 means an above-average contribution to the model; it is NOT a significance test and carries no error control.
A6: Metabolite | B6: KEGG ID | C6: Annotation confidence | D6: m/z | E6: RT (min) | F6: Mean peak area (control) | G6: SD (control) | H6: Mean peak area (CMVS) | I6: SD (CMVS) | J6: Mean peak area (all) | K6: Fold change | L6: log2 fold change | M6: |r| with group | N6: VIP score | O6: p-value (Welch) | P6: FDR q-value (BH) | Q6: VIP rank | R6: p-value rank | S6: Peak area rank | T6: Significant (p<0.05) | U6: Passes FDR<0.05 | V6: VIP > 1
A7: Betaine | C7: High | D7: 118.08616 | E7: 10.135 | F7: 1.6013639e+09 | G7: 98521385 | H7: 2.2767063e+09 | I7: 2.1430499e+08 | J7: 1.9083377e+09 | K7: 1.4217295 | L7: 0.50764702 | M7: 0.91796989 | N7: 8.2182722 | O7: 0.0009602154 | P7: 0.14718021 | Q7: =RANK(N7,$N$7:$N$307,0) -> 1 | R7: =RANK(O7,$O$7:$O$307,1) -> 1 | S7: =RANK(J7,$J$7:$J$307,0) -> 4 | T7: =IF(O7<0.05,"YES","no") -> YES | U7: =IF(P7<0.05,"YES","no") -> no | V7: =IF(N7>1,"YES","no") -> YES
A8: Creatine | B8: C00300 | C8: High | D8: 132.07663 | E8: 11.358 | F8: 3.4370523e+09 | G8: 8.4746457e+08 | H8: 2.9009166e+09 | I8: 3.3843656e+08 | J8: 3.1933542e+09 | K8: 0.84401292 | L8: -0.24466301 | M8: 0.40274256 | N8: 4.7840786 | O8: 0.19995314 | P8: 0.54579327 | Q8: =RANK(N8,$N$7:$N$307,0) -> 2 | R8: =RANK(O8,$O$7:$O$307,1) -> 107 | S8: =RANK(J8,$J$7:$J$307,0) -> 2 | T8: =IF(O8<0.05,"YES","no") -> no | U8: =IF(P8<0.05,"YES","no") -> no | V8: =IF(N8>1,"YES","no") -> YES
A9: L-Carnitine | B9: C00318 | C9: High | D9: 162.11233 | E9: 11.266 | F9: 7.3450876e+09 | G9: 1.0927004e+09 | H9: 6.6458806e+09 | I9: 1.5448571e+09 | J9: 7.0272663e+09 | K9: 0.90480617 | L9: -0.14431932 | M9: 0.28130323 | N9: 4.6214596 | O9: 0.42313391 | P9: 0.66582089 | Q9: =RANK(N9,$N$7:$N$307,0) -> 3 | R9: =RANK(O9,$O$7:$O$307,1) -> 190 | S9: =RANK(J9,$J$7:$J$307,0) -> 1 | T9: =IF(O9<0.05,"YES","no") -> no | U9: =IF(P9<0.05,"YES","no") -> no | V9: =IF(N9>1,"YES","no") -> YES
A10: DELTA-VALEROBETAINE | C10: Medium | D10: 160.13315 | E10: 12.211 | F10: 5.6063015e+08 | G10: 76103341 | H10: 8.3884985e+08 | I10: 2.1257389e+08 | J10: 6.8709365e+08 | K10: 1.4962625 | L10: 0.58136326 | M10: 0.70828084 | N10: 4.5698274 | O10: 0.040083048 | P10: 0.40216658 | Q10: =RANK(N10,$N$7:$N$307,0) -> 4 | R10: =RANK(O10,$O$7:$O$307,1) -> 30 | S10: =RANK(J10,$J$7:$J$307,0) -> 8 | T10: =IF(O10<0.05,"YES","no") -> YES | U10: =IF(P10<0.05,"YES","no") -> no | V10: =IF(N10>1,"YES","no") -> YES
A11: Glycerophosphocholine | C11: Medium | D11: 258.11003 | E11: 11.271 | F11: 6.0860635e+08 | G11: 1.3137991e+08 | H11: 3.8231895e+08 | I11: 65218992 | J11: 5.0574844e+08 | K11: 0.62818757 | L11: -0.67073269 | M11: 0.75813787 | N11: 4.447473 | O11: 0.0066066263 | P11: 0.19573647 | Q11: =RANK(N11,$N$7:$N$307,0) -> 5 | R11: =RANK(O11,$O$7:$O$307,1) -> 10 | S11: =RANK(J11,$J$7:$J$307,0) -> 9 | T11: =IF(O11<0.05,"YES","no") -> YES | U11: =IF(P11<0.05,"YES","no") -> no | V11: =IF(N11>1,"YES","no") -> YES
A12: O-Acetyl-L-carnitine | C12: High | D12: 204.12298 | E12: 10.121 | F12: 2.2298897e+09 | G12: 9.5094187e+08 | H12: 2.3419471e+09 | I12: 1.1632366e+09 | J12: 2.2808249e+09 | K12: 1.0502524 | L12: 0.070736093 | M12: 0.058613372 | N12: 4.2150265 | O12: 0.86735237 | P12: 0.91785702 | Q12: =RANK(N12,$N$7:$N$307,0) -> 6 | R12: =RANK(O12,$O$7:$O$307,1) -> 284 | S12: =RANK(J12,$J$7:$J$307,0) -> 3 | T12: =IF(O12<0.05,"YES","no") -> no | U12: =IF(P12<0.05,"YES","no") -> no | V12: =IF(N12>1,"YES","no") -> YES
A13: Taurine | B13: D00047 | C13: High | D13: 126.0218 | E13: 10.855 | F13: 8.6581155e+08 | G13: 1.5769059e+08 | H13: 1.0612794e+09 | I13: 1.4247296e+08 | J13: 9.5466057e+08 | K13: 1.2257626 | L13: 0.29367955 | M13: 0.58002802 | N13: 3.4665827 | O13: 0.059561572 | P13: 0.47339377 | Q13: =RANK(N13,$N$7:$N$307,0) -> 7 | R13: =RANK(O13,$O$7:$O$307,1) -> 36 | S13: =RANK(J13,$J$7:$J$307,0) -> 5 | T13: =IF(O13<0.05,"YES","no") -> no | U13: =IF(P13<0.05,"YES","no") -> no | V13: =IF(N13>1,"YES","no") -> YES
A14: Niacinamide | C14: High | D14: 123.05518 | E14: 6.893 | F14: 6.4653075e+08 | G14: 49672714 | H14: 7.7290274e+08 | I14: 54990245 | J14: 7.0397256e+08 | K14: 1.1954617 | L14: 0.25756789 | M14: 0.80039202 | N14: 3.3234163 | O14: 0.0039107318 | P14: 0.14718021 | Q14: =RANK(N14,$N$7:$N$307,0) -> 8 | R14: =RANK(O14,$O$7:$O$307,1) -> 7 | S14: =RANK(J14,$J$7:$J$307,0) -> 7 | T14: =IF(O14<0.05,"YES","no") -> YES | U14: =IF(P14<0.05,"YES","no") -> no | V14: =IF(N14>1,"YES","no") -> YES
A15: Glutamate | C15: High | D15: 148.06035 | E15: 9.8 | F15: 2.3600019e+08 | G15: 61126821 | H15: 3.5276652e+08 | I15: 1.03615e+08 | J15: 2.8907579e+08 | K15: 1.4947722 | L15: 0.57992564 | M15: 0.61344899 | N15: 2.7791424 | O15: 0.066640929 | P15: 0.47339377 | Q15: =RANK(N15,$N$7:$N$307,0) -> 9 | R15: =RANK(O15,$O$7:$O$307,1) -> 40 | S15: =RANK(J15,$J$7:$J$307,0) -> 15 | T15: =IF(O15<0.05,"YES","no") -> no | U15: =IF(P15<0.05,"YES","no") -> no | V15: =IF(N15>1,"YES","no") -> YES
A16: Deoxycarnitine | C16: High | D16: 146.11753 | E16: 11.962 | F16: 1.6805592e+08 | G16: 33151408 | H16: 2.4945779e+08 | I16: 31299106 | J16: 2.0505677e+08 | K16: 1.4843737 | L16: 0.56985435 | M16: 0.81086555 | N16: 2.6752689 | O16: 0.0024852722 | P16: 0.14718021 | Q16: =RANK(N16,$N$7:$N$307,0) -> 10 | R16: =RANK(O16,$O$7:$O$307,1) -> 4 | S16: =RANK(J16,$J$7:$J$307,0) -> 18 | T16: =IF(O16<0.05,"YES","no") -> YES | U16: =IF(P16<0.05,"YES","no") -> no | V16: =IF(N16>1,"YES","no") -> YES
A17: Adenosine | C17: High | D17: 268.104 | E17: 8.014 | F17: 1.5027716e+08 | G17: 32317167 | H17: 2.2588904e+08 | I17: 54515495 | J17: 1.846462e+08 | K17: 1.5031495 | L17: 0.58798853 | M17: 0.69050557 | N17: 2.366771 | O17: 0.03288087 | P17: 0.38914714 | Q17: =RANK(N17,$N$7:$N$307,0) -> 11 | R17: =RANK(O17,$O$7:$O$307,1) -> 24 | S17: =RANK(J17,$J$7:$J$307,0) -> 20 | T17: =IF(O17<0.05,"YES","no") -> YES | U17: =IF(P17<0.05,"YES","no") -> no | V17: =IF(N17>1,"YES","no") -> YES
A18: Lactic Acid | B18: D02111 | C18: Medium | D18: 89.02433 | E18: 7.221 | F18: 8.2984048e+08 | G18: 2.2728921e+08 | H18: 9.4047228e+08 | I18: 2.1863341e+08 | J18: 8.8012767e+08 | K18: 1.133317 | L18: 0.18055139 | M18: 0.26291944 | N18: 2.1950108 | O18: 0.43355779 | P18: 0.66582089 | Q18: =RANK(N18,$N$7:$N$307,0) -> 12 | R18: =RANK(O18,$O$7:$O$307,1) -> 196 | S18: =RANK(J18,$J$7:$J$307,0) -> 6 | T18: =IF(O18<0.05,"YES","no") -> no | U18: =IF(P18<0.05,"YES","no") -> no | V18: =IF(N18>1,"YES","no") -> YES
A19: Malate | C19: High | D19: 133.01415 | E19: 10.102 | F19: 2.6478539e+08 | G19: 1.1179083e+08 | H19: 2.0166939e+08 | I19: 1.3637928e+08 | J19: 2.360963e+08 | K19: 0.76163338 | L19: -0.39283139 | M19: 0.27117115 | N19: 2.075903 | O19: 0.43203062 | P19: 0.66582089 | Q19: =RANK(N19,$N$7:$N$307,0) -> 13 | R19: =RANK(O19,$O$7:$O$307,1) -> 193 | S19: =RANK(J19,$J$7:$J$307,0) -> 17 | T19: =IF(O19<0.05,"YES","no") -> no | U19: =IF(P19<0.05,"YES","no") -> no | V19: =IF(N19>1,"YES","no") -> YES
A20: Choline | C20: Medium | D20: 104.10686 | E20: 8.911 | F20: 4.9673945e+08 | G20: 1.9322909e+08 | H20: 3.9333218e+08 | I20: 1.9661186e+08 | J20: 4.4973614e+08 | K20: 0.79182796 | L20: -0.33674108 | M20: 0.28056646 | N20: 1.9671439 | O20: 0.40519638 | P20: 0.65221449 | Q20: =RANK(N20,$N$7:$N$307,0) -> 14 | R20: =RANK(O20,$O$7:$O$307,1) -> 187 | S20: =RANK(J20,$J$7:$J$307,0) -> 10 | T20: =IF(O20<0.05,"YES","no") -> no | U20: =IF(P20<0.05,"YES","no") -> no | V20: =IF(N20>1,"YES","no") -> YES
A21: 1-Palmitoyl-sn-glycero-3-Phosphocholine | C21: Medium | D21: 496.33971 | E21: 4.961 | F21: 1.8257648e+08 | G21: 66188937 | H21: 1.278154e+08 | I21: 22086611 | J21: 1.5768508e+08 | K21: 0.700065 | L21: -0.51443922 | M21: 0.50527337 | N21: 1.9076385 | O21: 0.10346394 | P21: 0.49609441 | Q21: =RANK(N21,$N$7:$N$307,0) -> 15 | R21: =RANK(O21,$O$7:$O$307,1) -> 62 | S21: =RANK(J21,$J$7:$J$307,0) -> 21 | T21: =IF(O21<0.05,"YES","no") -> no | U21: =IF(P21<0.05,"YES","no") -> no | V21: =IF(N21>1,"YES","no") -> YES
A22: AMP | C22: High | D22: 348.07036 | E22: 9.071 | F22: 2.6907483e+08 | G22: 37852083 | H22: 3.2427792e+08 | I22: 94615362 | J22: 2.9416714e+08 | K22: 1.2051589 | L22: 0.26922339 | M22: 0.40256882 | N22: 1.7848861 | O22: 0.27430124 | P22: 0.58974767 | Q22: =RANK(N22,$N$7:$N$307,0) -> 16 | R22: =RANK(O22,$O$7:$O$307,1) -> 140 | S22: =RANK(J22,$J$7:$J$307,0) -> 14 | T22: =IF(O22<0.05,"YES","no") -> no | U22: =IF(P22<0.05,"YES","no") -> no | V22: =IF(N22>1,"YES","no") -> YES
A23: L-Proline | C23: High | D23: 116.07051 | E23: 10.722 | F23: 3.6506777e+08 | G23: 90757280 | H23: 4.306073e+08 | I23: 65860301 | J23: 3.9485847e+08 | K23: 1.179527 | L23: 0.23820844 | M23: 0.40836246 | N23: 1.7641067 | O23: 0.19994261 | P23: 0.54579327 | Q23: =RANK(N23,$N$7:$N$307,0) -> 17 | R23: =RANK(O23,$O$7:$O$307,1) -> 106 | S23: =RANK(J23,$J$7:$J$307,0) -> 12 | T23: =IF(O23<0.05,"YES","no") -> no | U23: =IF(P23<0.05,"YES","no") -> no | V23: =IF(N23>1,"YES","no") -> YES
A24: Glycerol 3-Phosphate | C24: High | D24: 171.00639 | E24: 9.574 | F24: 74705719 | G24: 55240318 | H24: 1.296289e+08 | I24: 75625004 | J24: 99670802 | K24: 1.7351938 | L24: 0.7950968 | M24: 0.42125355 | N24: 1.7003683 | O24: 0.21752767 | P24: 0.54579327 | Q24: =RANK(N24,$N$7:$N$307,0) -> 18 | R24: =RANK(O24,$O$7:$O$307,1) -> 119 | S24: =RANK(J24,$J$7:$J$307,0) -> 28 | T24: =IF(O24<0.05,"YES","no") -> no | U24: =IF(P24<0.05,"YES","no") -> no | V24: =IF(N24>1,"YES","no") -> YES
A25: Glutathione Reduced | B25: C02471 | C25: High | D25: 308.09115 | E25: 9.381 | F25: 89683688 | G25: 19533518 | H25: 1.3269139e+08 | I25: 51749353 | J25: 1.0923264e+08 | K25: 1.4795487 | L25: 0.56515719 | M25: 0.53439474 | N25: 1.5711535 | O25: 0.13985343 | P25: 0.51387861 | Q25: =RANK(N25,$N$7:$N$307,0) -> 19 | R25: =RANK(O25,$O$7:$O$307,1) -> 81 | S25: =RANK(J25,$J$7:$J$307,0) -> 27 | T25: =IF(O25<0.05,"YES","no") -> no | U25: =IF(P25<0.05,"YES","no") -> no | V25: =IF(N25>1,"YES","no") -> YES
A26: Trimethylamine N-Oxide | C26: High | D26: 76.07564 | E26: 12.042 | F26: 24415264 | G26: 10740949 | H26: 51583034 | I26: 11557253 | J26: 36764251 | K26: 2.112737 | L26: 1.0791132 | M26: 0.80270639 | N26: 1.5423201 | O26: 0.0035656823 | P26: 0.14718021 | Q26: =RANK(N26,$N$7:$N$307,0) -> 20 | R26: =RANK(O26,$O$7:$O$307,1) -> 6 | S26: =RANK(J26,$J$7:$J$307,0) -> 52 | T26: =IF(O26<0.05,"YES","no") -> YES | U26: =IF(P26<0.05,"YES","no") -> no | V26: =IF(N26>1,"YES","no") -> YES
A27: L-Arginine | B27: C02385 | C27: High | D27: 175.11886 | E27: 18.84 | F27: 69884679 | G27: 21782184 | H27: 1.0398517e+08 | I27: 23859948 | J27: 85384901 | K27: 1.4879537 | L27: 0.57332966 | M27: 0.63679054 | N27: 1.5290336 | O27: 0.038629665 | P27: 0.40094928 | Q27: =RANK(N27,$N$7:$N$307,0) -> 21 | R27: =RANK(O27,$O$7:$O$307,1) -> 29 | S27: =RANK(J27,$J$7:$J$307,0) -> 32 | T27: =IF(O27<0.05,"YES","no") -> YES | U27: =IF(P27<0.05,"YES","no") -> no | V27: =IF(N27>1,"YES","no") -> YES
A28: Maltotetraose | C28: High | D28: 665.215 | E28: 11.713 | F28: 7899828.6 | G28: 8628621.3 | H28: 43583947 | I28: 43112153 | J28: 24119882 | K28: 5.517075 | L28: 2.4639036 | M28: 0.55486936 | N28: 1.5103527 | O28: 0.13825929 | P28: 0.51387861 | Q28: =RANK(N28,$N$7:$N$307,0) -> 22 | R28: =RANK(O28,$O$7:$O$307,1) -> 80 | S28: =RANK(J28,$J$7:$J$307,0) -> 70 | T28: =IF(O28<0.05,"YES","no") -> no | U28: =IF(P28<0.05,"YES","no") -> no | V28: =IF(N28>1,"YES","no") -> YES
A29: N-Acetylglutamate | C29: High | D29: 188.05646 | E29: 8.846 | F29: 14023712 | G29: 5398474.1 | H29: 38536621 | I29: 16669647 | J29: 25165944 | K29: 2.7479615 | L29: 1.4583618 | M29: 0.75224632 | N29: 1.4008465 | O29: 0.027523985 | P29: 0.37657816 | Q29: =RANK(N29,$N$7:$N$307,0) -> 23 | R29: =RANK(O29,$O$7:$O$307,1) -> 22 | S29: =RANK(J29,$J$7:$J$307,0) -> 69 | T29: =IF(O29<0.05,"YES","no") -> YES | U29: =IF(P29<0.05,"YES","no") -> no | V29: =IF(N29>1,"YES","no") -> YES
A30: Propionylcarnitine | B30: C03017 | C30: Medium | D30: 218.13866 | E30: 9.458 | F30: 2.6317393e+08 | G30: 1.3418639e+08 | H30: 3.0256215e+08 | I30: 92670155 | J30: 2.8107766e+08 | K30: 1.1496661 | L30: 0.20121497 | M30: 0.18138013 | N30: 1.2809341 | O30: 0.58077305 | P30: 0.76672231 | Q30: =RANK(N30,$N$7:$N$307,0) -> 24 | R30: =RANK(O30,$O$7:$O$307,1) -> 228 | S30: =RANK(J30,$J$7:$J$307,0) -> 16 | T30: =IF(O30<0.05,"YES","no") -> no | U30: =IF(P30<0.05,"YES","no") -> no | V30: =IF(N30>1,"YES","no") -> YES
A31: Galactose 1-phosphate | B31: C00103 | C31: High | D31: 259.02216 | E31: 10.206 | F31: 27695332 | G31: 13088079 | H31: 55080461 | I31: 44883716 | J31: 40143118 | K31: 1.9887994 | L31: 0.99189778 | M31: 0.43199037 | N31: 1.2778393 | O31: 0.24959081 | P31: 0.5853066 | Q31: =RANK(N31,$N$7:$N$307,0) -> 25 | R31: =RANK(O31,$O$7:$O$307,1) -> 128 | S31: =RANK(J31,$J$7:$J$307,0) -> 49 | T31: =IF(O31<0.05,"YES","no") -> no | U31: =IF(P31<0.05,"YES","no") -> no | V31: =IF(N31>1,"YES","no") -> YES
A32: ADP-Ribose | C32: High | D32: 558.06456 | E32: 9.061 | F32: 81600092 | G32: 21096383 | H32: 1.094183e+08 | I32: 38502717 | J32: 94244734 | K32: 1.3409091 | L32: 0.42321141 | M32: 0.45341999 | N32: 1.264182 | O32: 0.19898444 | P32: 0.54579327 | Q32: =RANK(N32,$N$7:$N$307,0) -> 26 | R32: =RANK(O32,$O$7:$O$307,1) -> 105 | S32: =RANK(J32,$J$7:$J$307,0) -> 29 | T32: =IF(O32<0.05,"YES","no") -> no | U32: =IF(P32<0.05,"YES","no") -> no | V32: =IF(N32>1,"YES","no") -> YES
A33: Phenylalanine | C33: High | D33: 166.08629 | E33: 8.757 | F33: 54632903 | G33: 13027139 | H33: 75214019 | I33: 20135056 | J33: 63987956 | K33: 1.3767165 | L33: 0.46123151 | M33: 0.56448571 | N33: 1.1557865 | O33: 0.092043988 | P33: 0.48686308 | Q33: =RANK(N33,$N$7:$N$307,0) -> 27 | R33: =RANK(O33,$O$7:$O$307,1) -> 56 | S33: =RANK(J33,$J$7:$J$307,0) -> 38 | T33: =IF(O33<0.05,"YES","no") -> no | U33: =IF(P33<0.05,"YES","no") -> no | V33: =IF(N33>1,"YES","no") -> YES
A34: Glucose 6-Phosphate | C34: High | D34: 259.02211 | E34: 10.095 | F34: 24720872 | G34: 9695298.3 | H34: 46161019 | I34: 36422703 | J34: 34466393 | K34: 1.8672893 | L34: 0.90094546 | M34: 0.42228989 | N34: 1.1269459 | O34: 0.26320137 | P34: 0.58974767 | Q34: =RANK(N34,$N$7:$N$307,0) -> 28 | R34: =RANK(O34,$O$7:$O$307,1) -> 133 | S34: =RANK(J34,$J$7:$J$307,0) -> 58 | T34: =IF(O34<0.05,"YES","no") -> no | U34: =IF(P34<0.05,"YES","no") -> no | V34: =IF(N34>1,"YES","no") -> YES
A35: Inosine | C35: High | D35: 269.08805 | E35: 8.957 | F35: 14264162 | G35: 6811101.9 | H35: 32561129 | I35: 21132470 | J35: 22580965 | K35: 2.2827229 | L35: 1.1907557 | M35: 0.55810023 | N35: 1.1153209 | O35: 0.12617491 | P35: 0.51387861 | Q35: =RANK(N35,$N$7:$N$307,0) -> 29 | R35: =RANK(O35,$O$7:$O$307,1) -> 69 | S35: =RANK(J35,$J$7:$J$307,0) -> 71 | T35: =IF(O35<0.05,"YES","no") -> no | U35: =IF(P35<0.05,"YES","no") -> no | V35: =IF(N35>1,"YES","no") -> YES
A36: Ergothioneine | C36: High | D36: 230.09567 | E36: 11.253 | F36: 69723076 | G36: 9809647.3 | H36: 52428399 | I36: 11632759 | J36: 61861859 | K36: 0.75195189 | L36: -0.41128774 | M36: 0.66616759 | N36: 1.1068831 | O36: 0.030236658 | P36: 0.38914714 | Q36: =RANK(N36,$N$7:$N$307,0) -> 30 | R36: =RANK(O36,$O$7:$O$307,1) -> 23 | S36: =RANK(J36,$J$7:$J$307,0) -> 39 | T36: =IF(O36<0.05,"YES","no") -> YES | U36: =IF(P36<0.05,"YES","no") -> no | V36: =IF(N36>1,"YES","no") -> YES
A37: Myoinositol | C37: High | D37: 179.0561 | E37: 11.841 | F37: 74148098 | G37: 7680258.3 | H37: 60374226 | I37: 6408120.1 | J37: 67887247 | K37: 0.81423837 | L37: -0.29647689 | M37: 0.72788186 | N37: 1.0714067 | O37: 0.010122877 | P37: 0.23438355 | Q37: =RANK(N37,$N$7:$N$307,0) -> 31 | R37: =RANK(O37,$O$7:$O$307,1) -> 13 | S37: =RANK(J37,$J$7:$J$307,0) -> 35 | T37: =IF(O37<0.05,"YES","no") -> YES | U37: =IF(P37<0.05,"YES","no") -> no | V37: =IF(N37>1,"YES","no") -> YES
A38: Raffinose | C38: Medium | D38: 522.20298 | E38: 11.479 | F38: 7572275.6 | G38: 7423496 | H38: 25396103 | I38: 21125186 | J38: 15674015 | K38: 3.3538271 | L38: 1.7458083 | M38: 0.54406337 | N38: 1.0704209 | O38: 0.13448259 | P38: 0.51387861 | Q38: =RANK(N38,$N$7:$N$307,0) -> 32 | R38: =RANK(O38,$O$7:$O$307,1) -> 75 | S38: =RANK(J38,$J$7:$J$307,0) -> 86 | T38: =IF(O38<0.05,"YES","no") -> no | U38: =IF(P38<0.05,"YES","no") -> no | V38: =IF(N38>1,"YES","no") -> YES
A39: Beta-NAD | C39: High | D39: 664.11651 | E39: 9.531 | F39: 40663557 | G39: 20248062 | H39: 20673265 | I39: 12289449 | J39: 31577061 | K39: 0.50839785 | L39: -0.97597016 | M39: 0.53953763 | N39: 1.0696923 | O39: 0.077295122 | P39: 0.48352202 | Q39: =RANK(N39,$N$7:$N$307,0) -> 33 | R39: =RANK(O39,$O$7:$O$307,1) -> 47 | S39: =RANK(J39,$J$7:$J$307,0) -> 61 | T39: =IF(O39<0.05,"YES","no") -> no | U39: =IF(P39<0.05,"YES","no") -> no | V39: =IF(N39>1,"YES","no") -> YES
A40: L-Glutathione oxidized | C40: Medium | D40: 611.14469 | E40: 10.174 | F40: 40267314 | G40: 10729977 | H40: 55903799 | I40: 7556098.2 | J40: 47374807 | K40: 1.3883171 | L40: 0.4733371 | M40: 0.6733147 | N40: 1.0564147 | O40: 0.020235809 | P40: 0.35409134 | Q40: =RANK(N40,$N$7:$N$307,0) -> 34 | R40: =RANK(O40,$O$7:$O$307,1) -> 17 | S40: =RANK(J40,$J$7:$J$307,0) -> 44 | T40: =IF(O40<0.05,"YES","no") -> YES | U40: =IF(P40<0.05,"YES","no") -> no | V40: =IF(N40>1,"YES","no") -> YES
A41: dGTP | B41: C00286 | C41: High | D41: 505.98835 | E41: 10.116 | F41: 71212169 | G41: 27744875 | H41: 46963098 | I41: 38086198 | J41: 60189864 | K41: 0.65948136 | L41: -0.60059621 | M41: 0.37747686 | N41: 1.0535833 | O41: 0.27350088 | P41: 0.58974767 | Q41: =RANK(N41,$N$7:$N$307,0) -> 35 | R41: =RANK(O41,$O$7:$O$307,1) -> 139 | S41: =RANK(J41,$J$7:$J$307,0) -> 40 | T41: =IF(O41<0.05,"YES","no") -> no | U41: =IF(P41<0.05,"YES","no") -> no | V41: =IF(N41>1,"YES","no") -> YES
...

Sheet BAT control vs CSDS
A1: BAT: control vs CSDS — VIP scores and p-values
A2: All 301 confidently annotated (L1/L2) metabolites, sorted by VIP descending. n = 6 control vs 6 CSDS.
A3: VIP from PLS-DA, 2 components, Pareto scaling, no log transform. p-value = Welch t-test (unequal variances). FDR = Benjamini-Hochberg across all 301 metabolites. Sample BAT_Aq_CMVS6 excluded as a multivariate outlier.
A4: VIP > 1 means an above-average contribution to the model; it is NOT a significance test and carries no error control.
A6: Metabolite | B6: KEGG ID | C6: Annotation confidence | D6: m/z | E6: RT (min) | F6: Mean peak area (control) | G6: SD (control) | H6: Mean peak area (CSDS) | I6: SD (CSDS) | J6: Mean peak area (all) | K6: Fold change | L6: log2 fold change | M6: |r| with group | N6: VIP score | O6: p-value (Welch) | P6: FDR q-value (BH) | Q6: VIP rank | R6: p-value rank | S6: Peak area rank | T6: Significant (p<0.05) | U6: Passes FDR<0.05 | V6: VIP > 1
A7: Betaine | C7: High | D7: 118.08616 | E7: 10.135 | F7: 1.6013639e+09 | G7: 98521385 | H7: 2.3053697e+09 | I7: 7.153557e+08 | J7: 1.9533668e+09 | K7: 1.4396289 | L7: 0.52569696 | M7: 0.60264152 | N7: 7.3327086 | O7: 0.060687979 | P7: 0.52419266 | Q7: =RANK(N7,$N$7:$N$307,0) -> 1 | R7: =RANK(O7,$O$7:$O$307,1) -> 34 | S7: =RANK(J7,$J$7:$J$307,0) -> 4 | T7: =IF(O7<0.05,"YES","no") -> no | U7: =IF(P7<0.05,"YES","no") -> no | V7: =IF(N7>1,"YES","no") -> YES
A8: Creatine | B8: C00300 | C8: High | D8: 132.07663 | E8: 11.358 | F8: 3.4370523e+09 | G8: 8.4746457e+08 | H8: 2.7486656e+09 | I8: 1.9645519e+08 | J8: 3.092859e+09 | K8: 0.79971597 | L8: -0.3224404 | M8: 0.52258676 | N8: 6.8705049 | O8: 0.10472459 | P8: 0.56289466 | Q8: =RANK(N8,$N$7:$N$307,0) -> 2 | R8: =RANK(O8,$O$7:$O$307,1) -> 56 | S8: =RANK(J8,$J$7:$J$307,0) -> 2 | T8: =IF(O8<0.05,"YES","no") -> no | U8: =IF(P8<0.05,"YES","no") -> no | V8: =IF(N8>1,"YES","no") -> YES
A9: L-Carnitine | B9: C00318 | C9: High | D9: 162.11233 | E9: 11.266 | F9: 7.3450876e+09 | G9: 1.0927004e+09 | H9: 7.8994221e+09 | I9: 1.3098276e+09 | J9: 7.6222548e+09 | K9: 1.0754701 | L9: 0.1049674 | M9: 0.24411042 | N9: 6.3217861 | O9: 0.44508234 | P9: 0.77987432 | Q9: =RANK(N9,$N$7:$N$307,0) -> 3 | R9: =RANK(O9,$O$7:$O$307,1) -> 171 | S9: =RANK(J9,$J$7:$J$307,0) -> 1 | T9: =IF(O9<0.05,"YES","no") -> no | U9: =IF(P9<0.05,"YES","no") -> no | V9: =IF(N9>1,"YES","no") -> YES
A10: Glycerophosphocholine | C10: Medium | D10: 258.11003 | E10: 11.271 | F10: 6.0860635e+08 | G10: 1.3137991e+08 | H10: 3.6758435e+08 | I10: 1.0299678e+08 | J10: 4.8809535e+08 | K10: 0.60397717 | L10: -0.72743407 | M10: 0.74544485 | N10: 5.6785508 | O10: 0.0058710974 | P10: 0.44787788 | Q10: =RANK(N10,$N$7:$N$307,0) -> 4 | R10: =RANK(O10,$O$7:$O$307,1) -> 3 | S10: =RANK(J10,$J$7:$J$307,0) -> 10 | T10: =IF(O10<0.05,"YES","no") -> YES | U10: =IF(P10<0.05,"YES","no") -> no | V10: =IF(N10>1,"YES","no") -> YES
A11: DELTA-VALEROBETAINE | C11: Medium | D11: 160.13315 | E11: 12.211 | F11: 5.6063015e+08 | G11: 76103341 | H11: 6.9591524e+08 | I11: 1.6034359e+08 | J11: 6.282727e+08 | K11: 1.241309 | L11: 0.31186227 | M11: 0.50841444 | N11: 2.998713 | O11: 0.10327781 | P11: 0.56289466 | Q11: =RANK(N11,$N$7:$N$307,0) -> 5 | R11: =RANK(O11,$O$7:$O$307,1) -> 55 | S11: =RANK(J11,$J$7:$J$307,0) -> 8 | T11: =IF(O11<0.05,"YES","no") -> no | U11: =IF(P11<0.05,"YES","no") -> no | V11: =IF(N11>1,"YES","no") -> YES
A12: Deoxycarnitine | C12: High | D12: 146.11753 | E12: 11.962 | F12: 1.6805592e+08 | G12: 33151408 | H12: 2.8148803e+08 | I12: 1.3310745e+08 | J12: 2.2477198e+08 | K12: 1.6749665 | L12: 0.74413223 | M12: 0.53937158 | N12: 2.8131327 | O12: 0.092431271 | P12: 0.54552574 | Q12: =RANK(N12,$N$7:$N$307,0) -> 6 | R12: =RANK(O12,$O$7:$O$307,1) -> 51 | S12: =RANK(J12,$J$7:$J$307,0) -> 17 | T12: =IF(O12<0.05,"YES","no") -> no | U12: =IF(P12<0.05,"YES","no") -> no | V12: =IF(N12>1,"YES","no") -> YES
A13: Malate | C13: High | D13: 133.01415 | E13: 10.102 | F13: 2.6478539e+08 | G13: 1.1179083e+08 | H13: 1.8254314e+08 | I13: 75061234 | J13: 2.2366427e+08 | K13: 0.68940037 | L13: -0.53658603 | M13: 0.42765677 | N13: 2.7661186 | O13: 0.16981339 | P13: 0.5908156 | Q13: =RANK(N13,$N$7:$N$307,0) -> 7 | R13: =RANK(O13,$O$7:$O$307,1) -> 84 | S13: =RANK(J13,$J$7:$J$307,0) -> 18 | T13: =IF(O13<0.05,"YES","no") -> no | U13: =IF(P13<0.05,"YES","no") -> no | V13: =IF(N13>1,"YES","no") -> YES
A14: Glycerol 3-Phosphate | C14: High | D14: 171.00639 | E14: 9.574 | F14: 74705719 | G14: 55240318 | H14: 1.707707e+08 | I14: 86534009 | J14: 1.2273821e+08 | K14: 2.285912 | L14: 1.1927698 | M14: 0.58687019 | N14: 2.6559001 | O14: 0.049266813 | P14: 0.47836486 | Q14: =RANK(N14,$N$7:$N$307,0) -> 8 | R14: =RANK(O14,$O$7:$O$307,1) -> 31 | S14: =RANK(J14,$J$7:$J$307,0) -> 26 | T14: =IF(O14<0.05,"YES","no") -> YES | U14: =IF(P14<0.05,"YES","no") -> no | V14: =IF(N14>1,"YES","no") -> YES
A15: Glutamine | C15: High | D15: 147.07637 | E15: 11.11 | F15: 3.8600151e+08 | G15: 49532539 | H15: 4.8103915e+08 | I15: 1.7257831e+08 | J15: 4.3352033e+08 | K15: 1.2462106 | L15: 0.31754784 | M15: 0.37936212 | N15: 2.3159061 | O15: 0.24382424 | P15: 0.64947874 | Q15: =RANK(N15,$N$7:$N$307,0) -> 9 | R15: =RANK(O15,$O$7:$O$307,1) -> 113 | S15: =RANK(J15,$J$7:$J$307,0) -> 11 | T15: =IF(O15<0.05,"YES","no") -> no | U15: =IF(P15<0.05,"YES","no") -> no | V15: =IF(N15>1,"YES","no") -> YES
A16: Glutathione Reduced | B16: C02471 | C16: High | D16: 308.09115 | E16: 9.381 | F16: 89683688 | G16: 19533518 | H16: 1.4851785e+08 | I16: 53354427 | J16: 1.1910077e+08 | K16: 1.6560186 | L16: 0.72771884 | M16: 0.62568718 | N16: 2.1595676 | O16: 0.042372091 | P16: 0.47836486 | Q16: =RANK(N16,$N$7:$N$307,0) -> 10 | R16: =RANK(O16,$O$7:$O$307,1) -> 25 | S16: =RANK(J16,$J$7:$J$307,0) -> 27 | T16: =IF(O16<0.05,"YES","no") -> YES | U16: =IF(P16<0.05,"YES","no") -> no | V16: =IF(N16>1,"YES","no") -> YES
A17: O-Acetyl-L-carnitine | C17: High | D17: 204.12298 | E17: 10.121 | F17: 2.2298897e+09 | G17: 9.5094187e+08 | H17: 2.1079345e+09 | I17: 8.2683602e+08 | J17: 2.1689121e+09 | K17: 0.94530884 | L17: -0.081142346 | M17: 0.074755141 | N17: 2.0809115 | O17: 0.81748703 | P17: 0.92348194 | Q17: =RANK(N17,$N$7:$N$307,0) -> 11 | R17: =RANK(O17,$O$7:$O$307,1) -> 264 | S17: =RANK(J17,$J$7:$J$307,0) -> 3 | T17: =IF(O17<0.05,"YES","no") -> no | U17: =IF(P17<0.05,"YES","no") -> no | V17: =IF(N17>1,"YES","no") -> YES
A18: Taurine | B18: D00047 | C18: High | D18: 126.0218 | E18: 10.855 | F18: 8.6581155e+08 | G18: 1.5769059e+08 | H18: 9.3164791e+08 | I18: 2.523251e+08 | J18: 8.9872973e+08 | K18: 1.0760401 | L18: 0.10573179 | M18: 0.16892697 | N18: 2.0752154 | O18: 0.60192626 | P18: 0.86276098 | Q18: =RANK(N18,$N$7:$N$307,0) -> 12 | R18: =RANK(O18,$O$7:$O$307,1) -> 210 | S18: =RANK(J18,$J$7:$J$307,0) -> 5 | T18: =IF(O18<0.05,"YES","no") -> no | U18: =IF(P18<0.05,"YES","no") -> no | V18: =IF(N18>1,"YES","no") -> YES
A19: Propionylcarnitine | B19: C03017 | C19: Medium | D19: 218.13866 | E19: 9.458 | F19: 2.6317393e+08 | G19: 1.3418639e+08 | H19: 3.0816728e+08 | I19: 1.2429885e+08 | J19: 2.856706e+08 | K19: 1.1709643 | L19: 0.22769713 | M19: 0.18717242 | N19: 1.8777133 | O19: 0.56030611 | P19: 0.83289283 | Q19: =RANK(N19,$N$7:$N$307,0) -> 13 | R19: =RANK(O19,$O$7:$O$307,1) -> 202 | S19: =RANK(J19,$J$7:$J$307,0) -> 15 | T19: =IF(O19<0.05,"YES","no") -> no | U19: =IF(P19<0.05,"YES","no") -> no | V19: =IF(N19>1,"YES","no") -> YES
A20: 1-Palmitoyl-sn-glycero-3-Phosphocholine | C20: Medium | D20: 496.33971 | E20: 4.961 | F20: 1.8257648e+08 | G20: 66188937 | H20: 1.3965269e+08 | I20: 22338783 | J20: 1.6111459e+08 | K20: 0.76489969 | L20: -0.38665753 | M20: 0.42975864 | N20: 1.8430054 | O20: 0.18201658 | P20: 0.5908156 | Q20: =RANK(N20,$N$7:$N$307,0) -> 14 | R20: =RANK(O20,$O$7:$O$307,1) -> 92 | S20: =RANK(J20,$J$7:$J$307,0) -> 21 | T20: =IF(O20<0.05,"YES","no") -> no | U20: =IF(P20<0.05,"YES","no") -> no | V20: =IF(N20>1,"YES","no") -> YES
A21: Lactic Acid | B21: D02111 | C21: Medium | D21: 89.02433 | E21: 7.221 | F21: 8.2984048e+08 | G21: 2.2728921e+08 | H21: 8.8091444e+08 | I21: 2.4882687e+08 | J21: 8.5537746e+08 | K21: 1.0615467 | L21: 0.086167867 | M21: 0.11659003 | N21: 1.7360168 | O21: 0.7182783 | P21: 0.89567378 | Q21: =RANK(N21,$N$7:$N$307,0) -> 15 | R21: =RANK(O21,$O$7:$O$307,1) -> 241 | S21: =RANK(J21,$J$7:$J$307,0) -> 6 | T21: =IF(O21<0.05,"YES","no") -> no | U21: =IF(P21<0.05,"YES","no") -> no | V21: =IF(N21>1,"YES","no") -> YES
A22: Creatinine | C22: High | D22: 114.06614 | E22: 8.762 | F22: 1.5251736e+08 | G22: 65663628 | H22: 1.1040673e+08 | I22: 10055607 | J22: 1.3146205e+08 | K22: 0.72389617 | L22: -0.46614531 | M22: 0.44076134 | N22: 1.6138898 | O22: 0.17858967 | P22: 0.5908156 | Q22: =RANK(N22,$N$7:$N$307,0) -> 16 | R22: =RANK(O22,$O$7:$O$307,1) -> 89 | S22: =RANK(J22,$J$7:$J$307,0) -> 24 | T22: =IF(O22<0.05,"YES","no") -> no | U22: =IF(P22<0.05,"YES","no") -> no | V22: =IF(N22>1,"YES","no") -> YES
A23: Myoinositol | C23: High | D23: 179.0561 | E23: 11.841 | F23: 74148098 | G23: 7680258.3 | H23: 54446366 | I23: 11366101 | J23: 64297232 | K23: 0.73429214 | L23: -0.44557393 | M23: 0.74370913 | N23: 1.58961 | O23: 0.0067953451 | P23: 0.44787788 | Q23: =RANK(N23,$N$7:$N$307,0) -> 17 | R23: =RANK(O23,$O$7:$O$307,1) -> 4 | S23: =RANK(J23,$J$7:$J$307,0) -> 36 | T23: =IF(O23<0.05,"YES","no") -> YES | U23: =IF(P23<0.05,"YES","no") -> no | V23: =IF(N23>1,"YES","no") -> YES
A24: dGTP | B24: C00286 | C24: High | D24: 505.98835 | E24: 10.116 | F24: 71212169 | G24: 27744875 | H24: 50359828 | I24: 40118058 | J24: 60785999 | K24: 0.7071801 | L24: -0.49985042 | M24: 0.3143532 | N24: 1.583185 | O24: 0.32265436 | P24: 0.67443723 | Q24: =RANK(N24,$N$7:$N$307,0) -> 18 | R24: =RANK(O24,$O$7:$O$307,1) -> 144 | S24: =RANK(J24,$J$7:$J$307,0) -> 40 | T24: =IF(O24<0.05,"YES","no") -> no | U24: =IF(P24<0.05,"YES","no") -> no | V24: =IF(N24>1,"YES","no") -> YES
A25: Niacinamide | C25: High | D25: 123.05518 | E25: 6.893 | F25: 6.4653075e+08 | G25: 49672714 | H25: 6.8055492e+08 | I25: 1.1400758e+08 | J25: 6.6354283e+08 | K25: 1.0526258 | L25: 0.073992604 | M25: 0.20732259 | N25: 1.5472236 | O25: 0.52474372 | P25: 0.82277423 | Q25: =RANK(N25,$N$7:$N$307,0) -> 19 | R25: =RANK(O25,$O$7:$O$307,1) -> 191 | S25: =RANK(J25,$J$7:$J$307,0) -> 7 | T25: =IF(O25<0.05,"YES","no") -> no | U25: =IF(P25<0.05,"YES","no") -> no | V25: =IF(N25>1,"YES","no") -> YES
A26: AMP | C26: High | D26: 348.07036 | E26: 9.071 | F26: 2.6907483e+08 | G26: 37852083 | H26: 3.075034e+08 | I26: 71792327 | J26: 2.8828912e+08 | K26: 1.1428174 | L26: 0.19259495 | M26: 0.34433665 | N26: 1.5269589 | O26: 0.28134754 | P26: 0.65206015 | Q26: =RANK(N26,$N$7:$N$307,0) -> 20 | R26: =RANK(O26,$O$7:$O$307,1) -> 127 | S26: =RANK(J26,$J$7:$J$307,0) -> 14 | T26: =IF(O26<0.05,"YES","no") -> no | U26: =IF(P26<0.05,"YES","no") -> no | V26: =IF(N26>1,"YES","no") -> YES
A27: Ergothioneine | C27: High | D27: 230.09567 | E27: 11.253 | F27: 69723076 | G27: 9809647.3 | H27: 51876264 | I27: 9355765.5 | J27: 60799670 | K27: 0.74403292 | L27: -0.42656164 | M27: 0.71400126 | N27: 1.3753143 | O27: 0.0091254229 | P27: 0.44787788 | Q27: =RANK(N27,$N$7:$N$307,0) -> 21 | R27: =RANK(O27,$O$7:$O$307,1) -> 5 | S27: =RANK(J27,$J$7:$J$307,0) -> 39 | T27: =IF(O27<0.05,"YES","no") -> YES | U27: =IF(P27<0.05,"YES","no") -> no | V27: =IF(N27>1,"YES","no") -> YES
A28: Pantothenate | C28: High | D28: 220.11801 | E28: 6.937 | F28: 1.1108854e+08 | G28: 39213954 | H28: 91805232 | I28: 31550614 | J28: 1.0144688e+08 | K28: 0.826415 | L28: -0.27506166 | M28: 0.28450845 | N28: 1.3651259 | O28: 0.37109847 | P28: 0.73973934 | Q28: =RANK(N28,$N$7:$N$307,0) -> 22 | R28: =RANK(O28,$O$7:$O$307,1) -> 151 | S28: =RANK(J28,$J$7:$J$307,0) -> 29 | T28: =IF(O28<0.05,"YES","no") -> no | U28: =IF(P28<0.05,"YES","no") -> no | V28: =IF(N28>1,"YES","no") -> YES
A29: Glutamate | C29: High | D29: 148.06035 | E29: 9.8 | F29: 2.3600019e+08 | G29: 61126821 | H29: 2.81571e+08 | I29: 1.072208e+08 | J29: 2.5878559e+08 | K29: 1.1930965 | L29: 0.25471075 | M29: 0.27497899 | N29: 1.3557538 | O29: 0.39238573 | P29: 0.74988898 | Q29: =RANK(N29,$N$7:$N$307,0) -> 23 | R29: =RANK(O29,$O$7:$O$307,1) -> 157 | S29: =RANK(J29,$J$7:$J$307,0) -> 16 | T29: =IF(O29<0.05,"YES","no") -> no | U29: =IF(P29<0.05,"YES","no") -> no | V29: =IF(N29>1,"YES","no") -> YES
A30: Beta-NAD | C30: High | D30: 664.11651 | E30: 9.531 | F30: 40663557 | G30: 20248062 | H30: 27878898 | I30: 17666289 | J30: 34271228 | K30: 0.68559909 | L30: -0.54456289 | M30: 0.34579449 | N30: 1.336377 | O30: 0.2713886 | P30: 0.65148254 | Q30: =RANK(N30,$N$7:$N$307,0) -> 24 | R30: =RANK(O30,$O$7:$O$307,1) -> 124 | S30: =RANK(J30,$J$7:$J$307,0) -> 55 | T30: =IF(O30<0.05,"YES","no") -> no | U30: =IF(P30<0.05,"YES","no") -> no | V30: =IF(N30>1,"YES","no") -> YES
A31: Trimethylamine N-Oxide | C31: High | D31: 76.07564 | E31: 12.042 | F31: 24415264 | G31: 10740949 | H31: 45355899 | I31: 23768321 | J31: 34885582 | K31: 1.8576862 | L31: 0.89350681 | M31: 0.52809966 | N31: 1.3335785 | O31: 0.090175913 | P31: 0.54552574 | Q31: =RANK(N31,$N$7:$N$307,0) -> 25 | R31: =RANK(O31,$O$7:$O$307,1) -> 47 | S31: =RANK(J31,$J$7:$J$307,0) -> 54 | T31: =IF(O31<0.05,"YES","no") -> no | U31: =IF(P31<0.05,"YES","no") -> no | V31: =IF(N31>1,"YES","no") -> YES
A32: Adenosine | C32: High | D32: 268.104 | E32: 8.014 | F32: 1.5027716e+08 | G32: 32317167 | H32: 1.791954e+08 | I32: 64245481 | J32: 1.6473628e+08 | K32: 1.1924327 | L32: 0.25390783 | M32: 0.29738329 | N32: 1.3081459 | O32: 0.35583076 | P32: 0.72860584 | Q32: =RANK(N32,$N$7:$N$307,0) -> 26 | R32: =RANK(O32,$O$7:$O$307,1) -> 147 | S32: =RANK(J32,$J$7:$J$307,0) -> 20 | T32: =IF(O32<0.05,"YES","no") -> no | U32: =IF(P32<0.05,"YES","no") -> no | V32: =IF(N32>1,"YES","no") -> YES
A33: Succinate | C33: High | D33: 117.01927 | E33: 9.349 | F33: 1.2633833e+08 | G33: 49902055 | H33: 1.5428011e+08 | I33: 75711022 | J33: 1.4030922e+08 | K33: 1.2211662 | L33: 0.2882596 | M33: 0.23216632 | N33: 1.2967727 | O33: 0.47040947 | P33: 0.78576173 | Q33: =RANK(N33,$N$7:$N$307,0) -> 27 | R33: =RANK(O33,$O$7:$O$307,1) -> 178 | S33: =RANK(J33,$J$7:$J$307,0) -> 22 | T33: =IF(O33<0.05,"YES","no") -> no | U33: =IF(P33<0.05,"YES","no") -> no | V33: =IF(N33>1,"YES","no") -> YES
A34: D-Pantothenic acid | C34: Medium | D34: 220.11791 | E34: 5.093 | F34: 37269055 | G34: 11137285 | H34: 24993701 | I34: 15865045 | J34: 31131378 | K34: 0.67062879 | L34: -0.57641368 | M34: 0.44039978 | N34: 1.2966888 | O34: 0.15539941 | P34: 0.5908156 | Q34: =RANK(N34,$N$7:$N$307,0) -> 28 | R34: =RANK(O34,$O$7:$O$307,1) -> 76 | S34: =RANK(J34,$J$7:$J$307,0) -> 61 | T34: =IF(O34<0.05,"YES","no") -> no | U34: =IF(P34<0.05,"YES","no") -> no | V34: =IF(N34>1,"YES","no") -> YES
A35: L-Arginine | B35: C02385 | C35: High | D35: 175.11886 | E35: 18.84 | F35: 69884679 | G35: 21782184 | H35: 93649259 | I35: 20217766 | J35: 81766969 | K35: 1.3400542 | L35: 0.42229138 | M35: 0.52657093 | N35: 1.2558624 | O35: 0.078763667 | P35: 0.54552574 | Q35: =RANK(N35,$N$7:$N$307,0) -> 29 | R35: =RANK(O35,$O$7:$O$307,1) -> 42 | S35: =RANK(J35,$J$7:$J$307,0) -> 32 | T35: =IF(O35<0.05,"YES","no") -> no | U35: =IF(P35<0.05,"YES","no") -> no | V35: =IF(N35>1,"YES","no") -> YES
A36: Phosphorylcholine | C36: High | D36: 184.07327 | E36: 11.86 | F36: 56305242 | G36: 40441006 | H36: 88239823 | I36: 58576988 | J36: 72272532 | K36: 1.5671689 | L36: 0.64816067 | M36: 0.32825784 | N36: 1.2405182 | O36: 0.30068309 | P36: 0.65206015 | Q36: =RANK(N36,$N$7:$N$307,0) -> 30 | R36: =RANK(O36,$O$7:$O$307,1) -> 137 | S36: =RANK(J36,$J$7:$J$307,0) -> 33 | T36: =IF(O36<0.05,"YES","no") -> no | U36: =IF(P36<0.05,"YES","no") -> no | V36: =IF(N36>1,"YES","no") -> YES
A37: L-Proline | C37: High | D37: 116.07051 | E37: 10.722 | F37: 3.6506777e+08 | G37: 90757280 | H37: 3.9371056e+08 | I37: 1.1182792e+08 | J37: 3.7938916e+08 | K37: 1.0784588 | L37: 0.10897107 | M37: 0.15225398 | N37: 1.1697145 | O37: 0.63709089 | P37: 0.88116818 | Q37: =RANK(N37,$N$7:$N$307,0) -> 31 | R37: =RANK(O37,$O$7:$O$307,1) -> 215 | S37: =RANK(J37,$J$7:$J$307,0) -> 12 | T37: =IF(O37<0.05,"YES","no") -> no | U37: =IF(P37<0.05,"YES","no") -> no | V37: =IF(N37>1,"YES","no") -> YES
A38: Choline | C38: Medium | D38: 104.10686 | E38: 8.911 | F38: 4.9673945e+08 | G38: 1.9322909e+08 | H38: 5.3840182e+08 | I38: 2.4543674e+08 | J38: 5.1757063e+08 | K38: 1.0838717 | L38: 0.11619397 | M38: 0.10276406 | N38: 1.1543963 | O38: 0.75099585 | P38: 0.90783033 | Q38: =RANK(N38,$N$7:$N$307,0) -> 32 | R38: =RANK(O38,$O$7:$O$307,1) -> 249 | S38: =RANK(J38,$J$7:$J$307,0) -> 9 | T38: =IF(O38<0.05,"YES","no") -> no | U38: =IF(P38<0.05,"YES","no") -> no | V38: =IF(N38>1,"YES","no") -> YES
A39: N-Acetylglutamate | C39: High | D39: 188.05646 | E39: 8.846 | F39: 14023712 | G39: 5398474.1 | H39: 29288551 | I39: 13374077 | J39: 21656132 | K39: 2.088502 | L39: 1.0624685 | M39: 0.63400317 | N39: 1.1003718 | O39: 0.037769416 | P39: 0.47836486 | Q39: =RANK(N39,$N$7:$N$307,0) -> 33 | R39: =RANK(O39,$O$7:$O$307,1) -> 21 | S39: =RANK(J39,$J$7:$J$307,0) -> 70 | T39: =IF(O39<0.05,"YES","no") -> YES | U39: =IF(P39<0.05,"YES","no") -> no | V39: =IF(N39>1,"YES","no") -> YES
A40: Sarcosine | C40: High | D40: 90.05487 | E40: 11.327 | F40: 1.3451455e+08 | G40: 32033880 | H40: 1.1428184e+08 | I40: 10221791 | J40: 1.243982e+08 | K40: 0.8495872 | L40: -0.23516607 | M40: 0.42245218 | N40: 1.0956942 | O40: 0.19088507 | P40: 0.59850422 | Q40: =RANK(N40,$N$7:$N$307,0) -> 34 | R40: =RANK(O40,$O$7:$O$307,1) -> 96 | S40: =RANK(J40,$J$7:$J$307,0) -> 25 | T40: =IF(O40<0.05,"YES","no") -> no | U40: =IF(P40<0.05,"YES","no") -> no | V40: =IF(N40>1,"YES","no") -> YES
A41: Maltotetraose | C41: High | D41: 665.215 | E41: 11.713 | F41: 7899828.6 | G41: 8628621.3 | H41: 24553105 | I41: 19208103 | J41: 16226467 | K41: 3.1080554 | L41: 1.6360122 | M41: 0.52237265 | N41: 1.076479 | O41: 0.094285812 | P41: 0.5457698 | Q41: =RANK(N41,$N$7:$N$307,0) -> 35 | R41: =RANK(O41,$O$7:$O$307,1) -> 52 | S41: =RANK(J41,$J$7:$J$307,0) -> 81 | T41: =IF(O41<0.05,"YES","no") -> no | U41: =IF(P41<0.05,"YES","no") -> no | V41: =IF(N41>1,"YES","no") -> YES
...

Sheet scW control vs CMVS
A1: scW: control vs CMVS — VIP scores and p-values
A2: All 301 confidently annotated (L1/L2) metabolites, sorted by VIP descending. n = 6 control vs 6 CMVS.
A3: VIP from PLS-DA, 2 components, Pareto scaling, no log transform. p-value = Welch t-test (unequal variances). FDR = Benjamini-Hochberg across all 301 metabolites.
A4: VIP > 1 means an above-average contribution to the model; it is NOT a significance test and carries no error control.
A6: Metabolite | B6: KEGG ID | C6: Annotation confidence | D6: m/z | E6: RT (min) | F6: Mean peak area (control) | G6: SD (control) | H6: Mean peak area (CMVS) | I6: SD (CMVS) | J6: Mean peak area (all) | K6: Fold change | L6: log2 fold change | M6: |r| with group | N6: VIP score | O6: p-value (Welch) | P6: FDR q-value (BH) | Q6: VIP rank | R6: p-value rank | S6: Peak area rank | T6: Significant (p<0.05) | U6: Passes FDR<0.05 | V6: VIP > 1
A7: L-Carnitine | B7: C00318 | C7: High | D7: 162.11233 | E7: 11.266 | F7: 1.0404348e+09 | G7: 3.8512585e+08 | H7: 2.0269431e+09 | I7: 3.3960831e+08 | J7: 1.5336889e+09 | K7: 1.9481692 | L7: 0.96211897 | M7: 0.83001763 | N7: 8.606609 | O7: 0.00086983914 | P7: 0.020140122 | Q7: =RANK(N7,$N$7:$N$307,0) -> 1 | R7: =RANK(O7,$O$7:$O$307,1) -> 13 | S7: =RANK(J7,$J$7:$J$307,0) -> 1 | T7: =IF(O7<0.05,"YES","no") -> YES | U7: =IF(P7<0.05,"YES","no") -> YES | V7: =IF(N7>1,"YES","no") -> YES
A8: Creatine | B8: C00300 | C8: High | D8: 132.07663 | E8: 11.358 | F8: 1.2824011e+09 | G8: 8.2581931e+08 | H8: 1.4078343e+09 | I8: 1.3147861e+08 | J8: 1.3451177e+09 | K8: 1.0978112 | L8: 0.13462996 | M8: 0.11541322 | N8: 5.5914859 | O8: 0.72764339 | P8: 0.81118763 | Q8: =RANK(N8,$N$7:$N$307,0) -> 2 | R8: =RANK(O8,$O$7:$O$307,1) -> 270 | S8: =RANK(J8,$J$7:$J$307,0) -> 2 | T8: =IF(O8<0.05,"YES","no") -> no | U8: =IF(P8<0.05,"YES","no") -> no | V8: =IF(N8>1,"YES","no") -> YES
A9: O-Acetyl-L-carnitine | C9: High | D9: 204.12298 | E9: 10.121 | F9: 4.4674362e+08 | G9: 2.5248505e+08 | H9: 3.9255033e+08 | I9: 1.0539847e+08 | J9: 4.1964698e+08 | K9: 0.87869265 | L9: -0.18656947 | M9: 0.15165297 | N9: 4.0320952 | O9: 0.64302801 | P9: 0.74157637 | Q9: =RANK(N9,$N$7:$N$307,0) -> 3 | R9: =RANK(O9,$O$7:$O$307,1) -> 261 | S9: =RANK(J9,$J$7:$J$307,0) -> 4 | T9: =IF(O9<0.05,"YES","no") -> no | U9: =IF(P9<0.05,"YES","no") -> no | V9: =IF(N9>1,"YES","no") -> YES
